{
 "cells": [
  {
   "cell_type": "code",
   "execution_count": 5,
   "metadata": {
    "collapsed": true,
    "pycharm": {
     "name": "#%%\n"
    }
   },
   "outputs": [],
   "source": [
    "import numpy as np\n",
    "\n",
    "import matplotlib.pyplot as plt\n",
    "\n",
    "import tensorflow as tf\n",
    "import tensorflow_io as tfio\n",
    "\n",
    "from tensorflow.python.keras.layers import Input, Conv1D, MaxPooling1D, UpSampling1D, LeakyReLU\n",
    "from tensorflow.python.keras.layers import Dense, GlobalAveragePooling1D\n",
    "from tensorflow.python.keras.regularizers import l2\n",
    "from tensorflow.python.keras.models import Model\n",
    "from tensorflow.python.keras.optimizers import adadelta_v2, adam_v2, nadam_v2, rmsprop_v2, adamax_v2\n",
    "from tensorflow.python.keras.callbacks import ModelCheckpoint\n",
    "\n",
    "import librosa\n",
    "import librosa.output as output\n",
    "import librosa.display\n",
    "\n",
    "import pathlib\n",
    "\n",
    "import IPython.display as ipd\n",
    "from tqdm.notebook import tqdm\n",
    "\n",
    "from time import time"
   ]
  },
  {
   "cell_type": "code",
   "execution_count": null,
   "outputs": [
    {
     "name": "stderr",
     "output_type": "stream",
     "text": [
      "ERROR:root:Internal Python error in the inspect module.\n",
      "Below is the traceback from this internal error.\n",
      "\n",
      "ERROR:root:Internal Python error in the inspect module.\n",
      "Below is the traceback from this internal error.\n",
      "\n"
     ]
    },
    {
     "name": "stdout",
     "output_type": "stream",
     "text": [
      "Traceback (most recent call last):\n",
      "  File \"C:\\Users\\Misha\\anaconda3\\lib\\site-packages\\IPython\\core\\interactiveshell.py\", line 3444, in run_code\n",
      "    exec(code_obj, self.user_global_ns, self.user_ns)\n",
      "  File \"C:\\Users\\Misha\\AppData\\Local\\Temp/ipykernel_10032/2908005114.py\", line 7, in <module>\n",
      "    test_audio = tfio.audio.decode_mp3(test_file)\n",
      "  File \"C:\\Users\\Misha\\anaconda3\\lib\\site-packages\\tensorflow_io\\python\\ops\\audio_ops.py\", line 593, in decode_mp3\n",
      "    return core_ops.io_audio_decode_mp3(input, shape=shape, name=name)\n",
      "  File \"<string>\", line 3473, in io_audio_decode_mp3\n",
      "KeyboardInterrupt\n",
      "\n",
      "During handling of the above exception, another exception occurred:\n",
      "\n",
      "Traceback (most recent call last):\n",
      "  File \"C:\\Users\\Misha\\anaconda3\\lib\\site-packages\\IPython\\core\\interactiveshell.py\", line 2064, in showtraceback\n",
      "    stb = value._render_traceback_()\n",
      "AttributeError: 'KeyboardInterrupt' object has no attribute '_render_traceback_'\n",
      "\n",
      "During handling of the above exception, another exception occurred:\n",
      "\n",
      "Traceback (most recent call last):\n",
      "  File \"C:\\Users\\Misha\\anaconda3\\lib\\site-packages\\IPython\\core\\ultratb.py\", line 1101, in get_records\n",
      "    return _fixed_getinnerframes(etb, number_of_lines_of_context, tb_offset)\n",
      "  File \"C:\\Users\\Misha\\anaconda3\\lib\\site-packages\\IPython\\core\\ultratb.py\", line 248, in wrapped\n",
      "    return f(*args, **kwargs)\n",
      "  File \"C:\\Users\\Misha\\anaconda3\\lib\\site-packages\\IPython\\core\\ultratb.py\", line 281, in _fixed_getinnerframes\n",
      "    records = fix_frame_records_filenames(inspect.getinnerframes(etb, context))\n",
      "  File \"C:\\Users\\Misha\\anaconda3\\lib\\inspect.py\", line 1541, in getinnerframes\n",
      "    frameinfo = (tb.tb_frame,) + getframeinfo(tb, context)\n",
      "  File \"C:\\Users\\Misha\\anaconda3\\lib\\inspect.py\", line 1499, in getframeinfo\n",
      "    filename = getsourcefile(frame) or getfile(frame)\n",
      "  File \"C:\\Users\\Misha\\anaconda3\\lib\\inspect.py\", line 709, in getsourcefile\n",
      "    if getattr(getmodule(object, filename), '__loader__', None) is not None:\n",
      "  File \"C:\\Users\\Misha\\anaconda3\\lib\\inspect.py\", line 755, in getmodule\n",
      "    os.path.realpath(f)] = module.__name__\n",
      "  File \"C:\\Users\\Misha\\anaconda3\\lib\\ntpath.py\", line 647, in realpath\n",
      "    path = _getfinalpathname(path)\n",
      "KeyboardInterrupt\n",
      "Traceback (most recent call last):\n",
      "  File \"C:\\Users\\Misha\\anaconda3\\lib\\site-packages\\IPython\\core\\interactiveshell.py\", line 3444, in run_code\n",
      "    exec(code_obj, self.user_global_ns, self.user_ns)\n",
      "  File \"C:\\Users\\Misha\\AppData\\Local\\Temp/ipykernel_10032/2908005114.py\", line 7, in <module>\n",
      "    test_audio = tfio.audio.decode_mp3(test_file)\n",
      "  File \"C:\\Users\\Misha\\anaconda3\\lib\\site-packages\\tensorflow_io\\python\\ops\\audio_ops.py\", line 593, in decode_mp3\n",
      "    return core_ops.io_audio_decode_mp3(input, shape=shape, name=name)\n",
      "  File \"<string>\", line 3473, in io_audio_decode_mp3\n",
      "KeyboardInterrupt\n",
      "\n",
      "During handling of the above exception, another exception occurred:\n",
      "\n",
      "Traceback (most recent call last):\n",
      "  File \"C:\\Users\\Misha\\anaconda3\\lib\\site-packages\\IPython\\core\\interactiveshell.py\", line 2064, in showtraceback\n",
      "    stb = value._render_traceback_()\n",
      "AttributeError: 'KeyboardInterrupt' object has no attribute '_render_traceback_'\n",
      "\n",
      "During handling of the above exception, another exception occurred:\n",
      "\n",
      "Traceback (most recent call last):\n",
      "  File \"C:\\Users\\Misha\\anaconda3\\lib\\site-packages\\IPython\\core\\interactiveshell.py\", line 3364, in run_ast_nodes\n",
      "    if (await self.run_code(code, result,  async_=asy)):\n",
      "  File \"C:\\Users\\Misha\\anaconda3\\lib\\site-packages\\IPython\\core\\interactiveshell.py\", line 3461, in run_code\n",
      "    self.showtraceback(running_compiled_code=True)\n",
      "  File \"C:\\Users\\Misha\\anaconda3\\lib\\site-packages\\IPython\\core\\interactiveshell.py\", line 2066, in showtraceback\n",
      "    stb = self.InteractiveTB.structured_traceback(etype,\n",
      "  File \"C:\\Users\\Misha\\anaconda3\\lib\\site-packages\\IPython\\core\\ultratb.py\", line 1367, in structured_traceback\n",
      "    return FormattedTB.structured_traceback(\n",
      "  File \"C:\\Users\\Misha\\anaconda3\\lib\\site-packages\\IPython\\core\\ultratb.py\", line 1267, in structured_traceback\n",
      "    return VerboseTB.structured_traceback(\n",
      "  File \"C:\\Users\\Misha\\anaconda3\\lib\\site-packages\\IPython\\core\\ultratb.py\", line 1124, in structured_traceback\n",
      "    formatted_exception = self.format_exception_as_a_whole(etype, evalue, etb, number_of_lines_of_context,\n",
      "  File \"C:\\Users\\Misha\\anaconda3\\lib\\site-packages\\IPython\\core\\ultratb.py\", line 1082, in format_exception_as_a_whole\n",
      "    last_unique, recursion_repeat = find_recursion(orig_etype, evalue, records)\n",
      "  File \"C:\\Users\\Misha\\anaconda3\\lib\\site-packages\\IPython\\core\\ultratb.py\", line 382, in find_recursion\n",
      "    return len(records), 0\n",
      "TypeError: object of type 'NoneType' has no len()\n",
      "\n",
      "During handling of the above exception, another exception occurred:\n",
      "\n",
      "Traceback (most recent call last):\n",
      "  File \"C:\\Users\\Misha\\anaconda3\\lib\\site-packages\\IPython\\core\\interactiveshell.py\", line 2064, in showtraceback\n",
      "    stb = value._render_traceback_()\n",
      "AttributeError: 'TypeError' object has no attribute '_render_traceback_'\n",
      "\n",
      "During handling of the above exception, another exception occurred:\n",
      "\n",
      "Traceback (most recent call last):\n",
      "  File \"C:\\Users\\Misha\\anaconda3\\lib\\site-packages\\IPython\\core\\ultratb.py\", line 1101, in get_records\n",
      "    return _fixed_getinnerframes(etb, number_of_lines_of_context, tb_offset)\n",
      "  File \"C:\\Users\\Misha\\anaconda3\\lib\\site-packages\\IPython\\core\\ultratb.py\", line 248, in wrapped\n",
      "    return f(*args, **kwargs)\n",
      "  File \"C:\\Users\\Misha\\anaconda3\\lib\\site-packages\\IPython\\core\\ultratb.py\", line 281, in _fixed_getinnerframes\n",
      "    records = fix_frame_records_filenames(inspect.getinnerframes(etb, context))\n",
      "  File \"C:\\Users\\Misha\\anaconda3\\lib\\inspect.py\", line 1541, in getinnerframes\n",
      "    frameinfo = (tb.tb_frame,) + getframeinfo(tb, context)\n",
      "  File \"C:\\Users\\Misha\\anaconda3\\lib\\inspect.py\", line 1499, in getframeinfo\n",
      "    filename = getsourcefile(frame) or getfile(frame)\n",
      "  File \"C:\\Users\\Misha\\anaconda3\\lib\\inspect.py\", line 709, in getsourcefile\n",
      "    if getattr(getmodule(object, filename), '__loader__', None) is not None:\n",
      "  File \"C:\\Users\\Misha\\anaconda3\\lib\\inspect.py\", line 755, in getmodule\n",
      "    os.path.realpath(f)] = module.__name__\n",
      "  File \"C:\\Users\\Misha\\anaconda3\\lib\\ntpath.py\", line 664, in realpath\n",
      "    if _getfinalpathname(spath) == path:\n",
      "KeyboardInterrupt\n"
     ]
    },
    {
     "name": "stderr",
     "output_type": "stream",
     "text": [
      "ERROR:root:Internal Python error in the inspect module.\n",
      "Below is the traceback from this internal error.\n",
      "\n"
     ]
    },
    {
     "name": "stdout",
     "output_type": "stream",
     "text": [
      "Traceback (most recent call last):\n",
      "  File \"C:\\Users\\Misha\\anaconda3\\lib\\site-packages\\IPython\\core\\interactiveshell.py\", line 3444, in run_code\n",
      "    exec(code_obj, self.user_global_ns, self.user_ns)\n",
      "  File \"C:\\Users\\Misha\\AppData\\Local\\Temp/ipykernel_10032/2908005114.py\", line 7, in <module>\n",
      "    test_audio = tfio.audio.decode_mp3(test_file)\n",
      "  File \"C:\\Users\\Misha\\anaconda3\\lib\\site-packages\\tensorflow_io\\python\\ops\\audio_ops.py\", line 593, in decode_mp3\n",
      "    return core_ops.io_audio_decode_mp3(input, shape=shape, name=name)\n",
      "  File \"<string>\", line 3473, in io_audio_decode_mp3\n",
      "KeyboardInterrupt\n",
      "\n",
      "During handling of the above exception, another exception occurred:\n",
      "\n",
      "Traceback (most recent call last):\n",
      "  File \"C:\\Users\\Misha\\anaconda3\\lib\\site-packages\\IPython\\core\\interactiveshell.py\", line 2064, in showtraceback\n",
      "    stb = value._render_traceback_()\n",
      "AttributeError: 'KeyboardInterrupt' object has no attribute '_render_traceback_'\n",
      "\n",
      "During handling of the above exception, another exception occurred:\n",
      "\n",
      "Traceback (most recent call last):\n",
      "  File \"C:\\Users\\Misha\\anaconda3\\lib\\site-packages\\IPython\\core\\interactiveshell.py\", line 3364, in run_ast_nodes\n",
      "    if (await self.run_code(code, result,  async_=asy)):\n",
      "  File \"C:\\Users\\Misha\\anaconda3\\lib\\site-packages\\IPython\\core\\interactiveshell.py\", line 3461, in run_code\n",
      "    self.showtraceback(running_compiled_code=True)\n",
      "  File \"C:\\Users\\Misha\\anaconda3\\lib\\site-packages\\IPython\\core\\interactiveshell.py\", line 2066, in showtraceback\n",
      "    stb = self.InteractiveTB.structured_traceback(etype,\n",
      "  File \"C:\\Users\\Misha\\anaconda3\\lib\\site-packages\\IPython\\core\\ultratb.py\", line 1367, in structured_traceback\n",
      "    return FormattedTB.structured_traceback(\n",
      "  File \"C:\\Users\\Misha\\anaconda3\\lib\\site-packages\\IPython\\core\\ultratb.py\", line 1267, in structured_traceback\n",
      "    return VerboseTB.structured_traceback(\n",
      "  File \"C:\\Users\\Misha\\anaconda3\\lib\\site-packages\\IPython\\core\\ultratb.py\", line 1124, in structured_traceback\n",
      "    formatted_exception = self.format_exception_as_a_whole(etype, evalue, etb, number_of_lines_of_context,\n",
      "  File \"C:\\Users\\Misha\\anaconda3\\lib\\site-packages\\IPython\\core\\ultratb.py\", line 1082, in format_exception_as_a_whole\n",
      "    last_unique, recursion_repeat = find_recursion(orig_etype, evalue, records)\n",
      "  File \"C:\\Users\\Misha\\anaconda3\\lib\\site-packages\\IPython\\core\\ultratb.py\", line 382, in find_recursion\n",
      "    return len(records), 0\n",
      "TypeError: object of type 'NoneType' has no len()\n",
      "\n",
      "During handling of the above exception, another exception occurred:\n",
      "\n",
      "Traceback (most recent call last):\n",
      "  File \"C:\\Users\\Misha\\anaconda3\\lib\\site-packages\\IPython\\core\\interactiveshell.py\", line 2064, in showtraceback\n",
      "    stb = value._render_traceback_()\n",
      "AttributeError: 'TypeError' object has no attribute '_render_traceback_'\n",
      "\n",
      "During handling of the above exception, another exception occurred:\n",
      "\n",
      "Traceback (most recent call last):\n",
      "  File \"C:\\Users\\Misha\\anaconda3\\lib\\site-packages\\IPython\\core\\interactiveshell.py\", line 2947, in _run_cell\n",
      "    return runner(coro)\n",
      "  File \"C:\\Users\\Misha\\anaconda3\\lib\\site-packages\\IPython\\core\\async_helpers.py\", line 68, in _pseudo_sync_runner\n",
      "    coro.send(None)\n",
      "  File \"C:\\Users\\Misha\\anaconda3\\lib\\site-packages\\IPython\\core\\interactiveshell.py\", line 3172, in run_cell_async\n",
      "    has_raised = await self.run_ast_nodes(code_ast.body, cell_name,\n",
      "  File \"C:\\Users\\Misha\\anaconda3\\lib\\site-packages\\IPython\\core\\interactiveshell.py\", line 3383, in run_ast_nodes\n",
      "    self.showtraceback()\n",
      "  File \"C:\\Users\\Misha\\anaconda3\\lib\\site-packages\\IPython\\core\\interactiveshell.py\", line 2066, in showtraceback\n",
      "    stb = self.InteractiveTB.structured_traceback(etype,\n",
      "  File \"C:\\Users\\Misha\\anaconda3\\lib\\site-packages\\IPython\\core\\ultratb.py\", line 1367, in structured_traceback\n",
      "    return FormattedTB.structured_traceback(\n",
      "  File \"C:\\Users\\Misha\\anaconda3\\lib\\site-packages\\IPython\\core\\ultratb.py\", line 1267, in structured_traceback\n",
      "    return VerboseTB.structured_traceback(\n",
      "  File \"C:\\Users\\Misha\\anaconda3\\lib\\site-packages\\IPython\\core\\ultratb.py\", line 1142, in structured_traceback\n",
      "    formatted_exceptions += self.format_exception_as_a_whole(etype, evalue, etb, lines_of_context,\n",
      "  File \"C:\\Users\\Misha\\anaconda3\\lib\\site-packages\\IPython\\core\\ultratb.py\", line 1082, in format_exception_as_a_whole\n",
      "    last_unique, recursion_repeat = find_recursion(orig_etype, evalue, records)\n",
      "  File \"C:\\Users\\Misha\\anaconda3\\lib\\site-packages\\IPython\\core\\ultratb.py\", line 382, in find_recursion\n",
      "    return len(records), 0\n",
      "TypeError: object of type 'NoneType' has no len()\n",
      "\n",
      "During handling of the above exception, another exception occurred:\n",
      "\n",
      "Traceback (most recent call last):\n",
      "  File \"C:\\Users\\Misha\\anaconda3\\lib\\site-packages\\IPython\\core\\interactiveshell.py\", line 2064, in showtraceback\n",
      "    stb = value._render_traceback_()\n",
      "AttributeError: 'TypeError' object has no attribute '_render_traceback_'\n",
      "\n",
      "During handling of the above exception, another exception occurred:\n",
      "\n",
      "Traceback (most recent call last):\n",
      "  File \"C:\\Users\\Misha\\anaconda3\\lib\\site-packages\\IPython\\core\\ultratb.py\", line 1101, in get_records\n",
      "    return _fixed_getinnerframes(etb, number_of_lines_of_context, tb_offset)\n",
      "  File \"C:\\Users\\Misha\\anaconda3\\lib\\site-packages\\IPython\\core\\ultratb.py\", line 248, in wrapped\n",
      "    return f(*args, **kwargs)\n",
      "  File \"C:\\Users\\Misha\\anaconda3\\lib\\site-packages\\IPython\\core\\ultratb.py\", line 281, in _fixed_getinnerframes\n",
      "    records = fix_frame_records_filenames(inspect.getinnerframes(etb, context))\n",
      "  File \"C:\\Users\\Misha\\anaconda3\\lib\\inspect.py\", line 1541, in getinnerframes\n",
      "    frameinfo = (tb.tb_frame,) + getframeinfo(tb, context)\n",
      "  File \"C:\\Users\\Misha\\anaconda3\\lib\\inspect.py\", line 1499, in getframeinfo\n",
      "    filename = getsourcefile(frame) or getfile(frame)\n",
      "  File \"C:\\Users\\Misha\\anaconda3\\lib\\inspect.py\", line 709, in getsourcefile\n",
      "    if getattr(getmodule(object, filename), '__loader__', None) is not None:\n",
      "  File \"C:\\Users\\Misha\\anaconda3\\lib\\inspect.py\", line 755, in getmodule\n",
      "    os.path.realpath(f)] = module.__name__\n",
      "  File \"C:\\Users\\Misha\\anaconda3\\lib\\ntpath.py\", line 664, in realpath\n",
      "    if _getfinalpathname(spath) == path:\n",
      "KeyboardInterrupt\n"
     ]
    }
   ],
   "source": [
    "fol1 = \"ternovsky\"\n",
    "# fol2 = \"ternovsky2\"\n",
    "# fol3 = \"ternovsky3\"\n",
    "\n",
    "for i in range(100):\n",
    "    test_file = tf.io.read_file(fol1 + \"/\" + str(i) + \".mp3\")\n",
    "    test_audio = tfio.audio.decode_mp3(test_file)\n",
    "\n",
    "    rows, columns = test_audio.shape\n",
    "    mas_len = len(test_audio)\n",
    "    true_audio = tf.reshape(test_audio, [rows * columns])\n",
    "    np.save(\"numpy_array/\" + fol1 + \"_np/\" +  str(i) + \".npy\", true_audio)"
   ],
   "metadata": {
    "collapsed": false,
    "pycharm": {
     "name": "#%%\n",
     "is_executing": true
    }
   }
  },
  {
   "cell_type": "code",
   "execution_count": null,
   "outputs": [
    {
     "name": "stdout",
     "output_type": "stream",
     "text": [
      "ERROR! Session/line number was not unique in database. History logging moved to new session 22\n"
     ]
    },
    {
     "name": "stderr",
     "output_type": "stream",
     "text": [
      "ERROR:root:Internal Python error in the inspect module.\n",
      "Below is the traceback from this internal error.\n",
      "\n",
      "ERROR:root:Internal Python error in the inspect module.\n",
      "Below is the traceback from this internal error.\n",
      "\n"
     ]
    },
    {
     "name": "stdout",
     "output_type": "stream",
     "text": [
      "Traceback (most recent call last):\n",
      "  File \"C:\\Users\\Misha\\anaconda3\\lib\\site-packages\\IPython\\core\\interactiveshell.py\", line 3444, in run_code\n",
      "    exec(code_obj, self.user_global_ns, self.user_ns)\n",
      "  File \"C:\\Users\\Misha\\AppData\\Local\\Temp/ipykernel_10032/1901517395.py\", line 5, in <module>\n",
      "    test_audio = tfio.audio.decode_mp3(test_file)\n",
      "  File \"C:\\Users\\Misha\\anaconda3\\lib\\site-packages\\tensorflow_io\\python\\ops\\audio_ops.py\", line 593, in decode_mp3\n",
      "    return core_ops.io_audio_decode_mp3(input, shape=shape, name=name)\n",
      "  File \"<string>\", line 3473, in io_audio_decode_mp3\n",
      "KeyboardInterrupt\n",
      "\n",
      "During handling of the above exception, another exception occurred:\n",
      "\n",
      "Traceback (most recent call last):\n",
      "  File \"C:\\Users\\Misha\\anaconda3\\lib\\site-packages\\IPython\\core\\interactiveshell.py\", line 2064, in showtraceback\n",
      "    stb = value._render_traceback_()\n",
      "AttributeError: 'KeyboardInterrupt' object has no attribute '_render_traceback_'\n",
      "\n",
      "During handling of the above exception, another exception occurred:\n",
      "\n",
      "Traceback (most recent call last):\n",
      "  File \"C:\\Users\\Misha\\anaconda3\\lib\\site-packages\\IPython\\core\\ultratb.py\", line 1101, in get_records\n",
      "    return _fixed_getinnerframes(etb, number_of_lines_of_context, tb_offset)\n",
      "  File \"C:\\Users\\Misha\\anaconda3\\lib\\site-packages\\IPython\\core\\ultratb.py\", line 248, in wrapped\n",
      "    return f(*args, **kwargs)\n",
      "  File \"C:\\Users\\Misha\\anaconda3\\lib\\site-packages\\IPython\\core\\ultratb.py\", line 281, in _fixed_getinnerframes\n",
      "    records = fix_frame_records_filenames(inspect.getinnerframes(etb, context))\n",
      "  File \"C:\\Users\\Misha\\anaconda3\\lib\\inspect.py\", line 1541, in getinnerframes\n",
      "    frameinfo = (tb.tb_frame,) + getframeinfo(tb, context)\n",
      "  File \"C:\\Users\\Misha\\anaconda3\\lib\\inspect.py\", line 1499, in getframeinfo\n",
      "    filename = getsourcefile(frame) or getfile(frame)\n",
      "  File \"C:\\Users\\Misha\\anaconda3\\lib\\inspect.py\", line 709, in getsourcefile\n",
      "    if getattr(getmodule(object, filename), '__loader__', None) is not None:\n",
      "  File \"C:\\Users\\Misha\\anaconda3\\lib\\inspect.py\", line 752, in getmodule\n",
      "    f = getabsfile(module)\n",
      "  File \"C:\\Users\\Misha\\anaconda3\\lib\\inspect.py\", line 721, in getabsfile\n",
      "    _filename = getsourcefile(object) or getfile(object)\n",
      "  File \"C:\\Users\\Misha\\anaconda3\\lib\\inspect.py\", line 706, in getsourcefile\n",
      "    if os.path.exists(filename):\n",
      "  File \"C:\\Users\\Misha\\anaconda3\\lib\\genericpath.py\", line 19, in exists\n",
      "    os.stat(path)\n",
      "KeyboardInterrupt\n",
      "Traceback (most recent call last):\n",
      "  File \"C:\\Users\\Misha\\anaconda3\\lib\\site-packages\\IPython\\core\\interactiveshell.py\", line 3444, in run_code\n",
      "    exec(code_obj, self.user_global_ns, self.user_ns)\n",
      "  File \"C:\\Users\\Misha\\AppData\\Local\\Temp/ipykernel_10032/1901517395.py\", line 5, in <module>\n",
      "    test_audio = tfio.audio.decode_mp3(test_file)\n",
      "  File \"C:\\Users\\Misha\\anaconda3\\lib\\site-packages\\tensorflow_io\\python\\ops\\audio_ops.py\", line 593, in decode_mp3\n",
      "    return core_ops.io_audio_decode_mp3(input, shape=shape, name=name)\n",
      "  File \"<string>\", line 3473, in io_audio_decode_mp3\n",
      "KeyboardInterrupt\n",
      "\n",
      "During handling of the above exception, another exception occurred:\n",
      "\n",
      "Traceback (most recent call last):\n",
      "  File \"C:\\Users\\Misha\\anaconda3\\lib\\site-packages\\IPython\\core\\interactiveshell.py\", line 2064, in showtraceback\n",
      "    stb = value._render_traceback_()\n",
      "AttributeError: 'KeyboardInterrupt' object has no attribute '_render_traceback_'\n",
      "\n",
      "During handling of the above exception, another exception occurred:\n",
      "\n",
      "Traceback (most recent call last):\n",
      "  File \"C:\\Users\\Misha\\anaconda3\\lib\\site-packages\\IPython\\core\\interactiveshell.py\", line 3364, in run_ast_nodes\n",
      "    if (await self.run_code(code, result,  async_=asy)):\n",
      "  File \"C:\\Users\\Misha\\anaconda3\\lib\\site-packages\\IPython\\core\\interactiveshell.py\", line 3461, in run_code\n",
      "    self.showtraceback(running_compiled_code=True)\n",
      "  File \"C:\\Users\\Misha\\anaconda3\\lib\\site-packages\\IPython\\core\\interactiveshell.py\", line 2066, in showtraceback\n",
      "    stb = self.InteractiveTB.structured_traceback(etype,\n",
      "  File \"C:\\Users\\Misha\\anaconda3\\lib\\site-packages\\IPython\\core\\ultratb.py\", line 1367, in structured_traceback\n",
      "    return FormattedTB.structured_traceback(\n",
      "  File \"C:\\Users\\Misha\\anaconda3\\lib\\site-packages\\IPython\\core\\ultratb.py\", line 1267, in structured_traceback\n",
      "    return VerboseTB.structured_traceback(\n",
      "  File \"C:\\Users\\Misha\\anaconda3\\lib\\site-packages\\IPython\\core\\ultratb.py\", line 1124, in structured_traceback\n",
      "    formatted_exception = self.format_exception_as_a_whole(etype, evalue, etb, number_of_lines_of_context,\n",
      "  File \"C:\\Users\\Misha\\anaconda3\\lib\\site-packages\\IPython\\core\\ultratb.py\", line 1082, in format_exception_as_a_whole\n",
      "    last_unique, recursion_repeat = find_recursion(orig_etype, evalue, records)\n",
      "  File \"C:\\Users\\Misha\\anaconda3\\lib\\site-packages\\IPython\\core\\ultratb.py\", line 382, in find_recursion\n",
      "    return len(records), 0\n",
      "TypeError: object of type 'NoneType' has no len()\n",
      "\n",
      "During handling of the above exception, another exception occurred:\n",
      "\n",
      "Traceback (most recent call last):\n",
      "  File \"C:\\Users\\Misha\\anaconda3\\lib\\site-packages\\IPython\\core\\interactiveshell.py\", line 2064, in showtraceback\n",
      "    stb = value._render_traceback_()\n",
      "AttributeError: 'TypeError' object has no attribute '_render_traceback_'\n",
      "\n",
      "During handling of the above exception, another exception occurred:\n",
      "\n",
      "Traceback (most recent call last):\n",
      "  File \"C:\\Users\\Misha\\anaconda3\\lib\\site-packages\\IPython\\core\\ultratb.py\", line 1101, in get_records\n",
      "    return _fixed_getinnerframes(etb, number_of_lines_of_context, tb_offset)\n",
      "  File \"C:\\Users\\Misha\\anaconda3\\lib\\site-packages\\IPython\\core\\ultratb.py\", line 248, in wrapped\n",
      "    return f(*args, **kwargs)\n",
      "  File \"C:\\Users\\Misha\\anaconda3\\lib\\site-packages\\IPython\\core\\ultratb.py\", line 281, in _fixed_getinnerframes\n",
      "    records = fix_frame_records_filenames(inspect.getinnerframes(etb, context))\n",
      "  File \"C:\\Users\\Misha\\anaconda3\\lib\\inspect.py\", line 1541, in getinnerframes\n",
      "    frameinfo = (tb.tb_frame,) + getframeinfo(tb, context)\n",
      "  File \"C:\\Users\\Misha\\anaconda3\\lib\\inspect.py\", line 1499, in getframeinfo\n",
      "    filename = getsourcefile(frame) or getfile(frame)\n",
      "  File \"C:\\Users\\Misha\\anaconda3\\lib\\inspect.py\", line 709, in getsourcefile\n",
      "    if getattr(getmodule(object, filename), '__loader__', None) is not None:\n",
      "  File \"C:\\Users\\Misha\\anaconda3\\lib\\inspect.py\", line 752, in getmodule\n",
      "    f = getabsfile(module)\n",
      "  File \"C:\\Users\\Misha\\anaconda3\\lib\\inspect.py\", line 721, in getabsfile\n",
      "    _filename = getsourcefile(object) or getfile(object)\n",
      "  File \"C:\\Users\\Misha\\anaconda3\\lib\\inspect.py\", line 706, in getsourcefile\n",
      "    if os.path.exists(filename):\n",
      "  File \"C:\\Users\\Misha\\anaconda3\\lib\\genericpath.py\", line 19, in exists\n",
      "    os.stat(path)\n",
      "KeyboardInterrupt\n"
     ]
    },
    {
     "name": "stderr",
     "output_type": "stream",
     "text": [
      "ERROR:root:Internal Python error in the inspect module.\n",
      "Below is the traceback from this internal error.\n",
      "\n"
     ]
    },
    {
     "name": "stdout",
     "output_type": "stream",
     "text": [
      "Traceback (most recent call last):\n",
      "  File \"C:\\Users\\Misha\\anaconda3\\lib\\site-packages\\IPython\\core\\interactiveshell.py\", line 3444, in run_code\n",
      "    exec(code_obj, self.user_global_ns, self.user_ns)\n",
      "  File \"C:\\Users\\Misha\\AppData\\Local\\Temp/ipykernel_10032/1901517395.py\", line 5, in <module>\n",
      "    test_audio = tfio.audio.decode_mp3(test_file)\n",
      "  File \"C:\\Users\\Misha\\anaconda3\\lib\\site-packages\\tensorflow_io\\python\\ops\\audio_ops.py\", line 593, in decode_mp3\n",
      "    return core_ops.io_audio_decode_mp3(input, shape=shape, name=name)\n",
      "  File \"<string>\", line 3473, in io_audio_decode_mp3\n",
      "KeyboardInterrupt\n",
      "\n",
      "During handling of the above exception, another exception occurred:\n",
      "\n",
      "Traceback (most recent call last):\n",
      "  File \"C:\\Users\\Misha\\anaconda3\\lib\\site-packages\\IPython\\core\\interactiveshell.py\", line 2064, in showtraceback\n",
      "    stb = value._render_traceback_()\n",
      "AttributeError: 'KeyboardInterrupt' object has no attribute '_render_traceback_'\n",
      "\n",
      "During handling of the above exception, another exception occurred:\n",
      "\n",
      "Traceback (most recent call last):\n",
      "  File \"C:\\Users\\Misha\\anaconda3\\lib\\site-packages\\IPython\\core\\interactiveshell.py\", line 3364, in run_ast_nodes\n",
      "    if (await self.run_code(code, result,  async_=asy)):\n",
      "  File \"C:\\Users\\Misha\\anaconda3\\lib\\site-packages\\IPython\\core\\interactiveshell.py\", line 3461, in run_code\n",
      "    self.showtraceback(running_compiled_code=True)\n",
      "  File \"C:\\Users\\Misha\\anaconda3\\lib\\site-packages\\IPython\\core\\interactiveshell.py\", line 2066, in showtraceback\n",
      "    stb = self.InteractiveTB.structured_traceback(etype,\n",
      "  File \"C:\\Users\\Misha\\anaconda3\\lib\\site-packages\\IPython\\core\\ultratb.py\", line 1367, in structured_traceback\n",
      "    return FormattedTB.structured_traceback(\n",
      "  File \"C:\\Users\\Misha\\anaconda3\\lib\\site-packages\\IPython\\core\\ultratb.py\", line 1267, in structured_traceback\n",
      "    return VerboseTB.structured_traceback(\n",
      "  File \"C:\\Users\\Misha\\anaconda3\\lib\\site-packages\\IPython\\core\\ultratb.py\", line 1124, in structured_traceback\n",
      "    formatted_exception = self.format_exception_as_a_whole(etype, evalue, etb, number_of_lines_of_context,\n",
      "  File \"C:\\Users\\Misha\\anaconda3\\lib\\site-packages\\IPython\\core\\ultratb.py\", line 1082, in format_exception_as_a_whole\n",
      "    last_unique, recursion_repeat = find_recursion(orig_etype, evalue, records)\n",
      "  File \"C:\\Users\\Misha\\anaconda3\\lib\\site-packages\\IPython\\core\\ultratb.py\", line 382, in find_recursion\n",
      "    return len(records), 0\n",
      "TypeError: object of type 'NoneType' has no len()\n",
      "\n",
      "During handling of the above exception, another exception occurred:\n",
      "\n",
      "Traceback (most recent call last):\n",
      "  File \"C:\\Users\\Misha\\anaconda3\\lib\\site-packages\\IPython\\core\\interactiveshell.py\", line 2064, in showtraceback\n",
      "    stb = value._render_traceback_()\n",
      "AttributeError: 'TypeError' object has no attribute '_render_traceback_'\n",
      "\n",
      "During handling of the above exception, another exception occurred:\n",
      "\n",
      "Traceback (most recent call last):\n",
      "  File \"C:\\Users\\Misha\\anaconda3\\lib\\site-packages\\IPython\\core\\interactiveshell.py\", line 2947, in _run_cell\n",
      "    return runner(coro)\n",
      "  File \"C:\\Users\\Misha\\anaconda3\\lib\\site-packages\\IPython\\core\\async_helpers.py\", line 68, in _pseudo_sync_runner\n",
      "    coro.send(None)\n",
      "  File \"C:\\Users\\Misha\\anaconda3\\lib\\site-packages\\IPython\\core\\interactiveshell.py\", line 3172, in run_cell_async\n",
      "    has_raised = await self.run_ast_nodes(code_ast.body, cell_name,\n",
      "  File \"C:\\Users\\Misha\\anaconda3\\lib\\site-packages\\IPython\\core\\interactiveshell.py\", line 3383, in run_ast_nodes\n",
      "    self.showtraceback()\n",
      "  File \"C:\\Users\\Misha\\anaconda3\\lib\\site-packages\\IPython\\core\\interactiveshell.py\", line 2066, in showtraceback\n",
      "    stb = self.InteractiveTB.structured_traceback(etype,\n",
      "  File \"C:\\Users\\Misha\\anaconda3\\lib\\site-packages\\IPython\\core\\ultratb.py\", line 1367, in structured_traceback\n",
      "    return FormattedTB.structured_traceback(\n",
      "  File \"C:\\Users\\Misha\\anaconda3\\lib\\site-packages\\IPython\\core\\ultratb.py\", line 1267, in structured_traceback\n",
      "    return VerboseTB.structured_traceback(\n",
      "  File \"C:\\Users\\Misha\\anaconda3\\lib\\site-packages\\IPython\\core\\ultratb.py\", line 1142, in structured_traceback\n",
      "    formatted_exceptions += self.format_exception_as_a_whole(etype, evalue, etb, lines_of_context,\n",
      "  File \"C:\\Users\\Misha\\anaconda3\\lib\\site-packages\\IPython\\core\\ultratb.py\", line 1082, in format_exception_as_a_whole\n",
      "    last_unique, recursion_repeat = find_recursion(orig_etype, evalue, records)\n",
      "  File \"C:\\Users\\Misha\\anaconda3\\lib\\site-packages\\IPython\\core\\ultratb.py\", line 382, in find_recursion\n",
      "    return len(records), 0\n",
      "TypeError: object of type 'NoneType' has no len()\n",
      "\n",
      "During handling of the above exception, another exception occurred:\n",
      "\n",
      "Traceback (most recent call last):\n",
      "  File \"C:\\Users\\Misha\\anaconda3\\lib\\site-packages\\IPython\\core\\interactiveshell.py\", line 2064, in showtraceback\n",
      "    stb = value._render_traceback_()\n",
      "AttributeError: 'TypeError' object has no attribute '_render_traceback_'\n",
      "\n",
      "During handling of the above exception, another exception occurred:\n",
      "\n",
      "Traceback (most recent call last):\n",
      "  File \"C:\\Users\\Misha\\anaconda3\\lib\\site-packages\\IPython\\core\\ultratb.py\", line 1101, in get_records\n",
      "    return _fixed_getinnerframes(etb, number_of_lines_of_context, tb_offset)\n",
      "  File \"C:\\Users\\Misha\\anaconda3\\lib\\site-packages\\IPython\\core\\ultratb.py\", line 248, in wrapped\n",
      "    return f(*args, **kwargs)\n",
      "  File \"C:\\Users\\Misha\\anaconda3\\lib\\site-packages\\IPython\\core\\ultratb.py\", line 281, in _fixed_getinnerframes\n",
      "    records = fix_frame_records_filenames(inspect.getinnerframes(etb, context))\n",
      "  File \"C:\\Users\\Misha\\anaconda3\\lib\\inspect.py\", line 1541, in getinnerframes\n",
      "    frameinfo = (tb.tb_frame,) + getframeinfo(tb, context)\n",
      "  File \"C:\\Users\\Misha\\anaconda3\\lib\\inspect.py\", line 1499, in getframeinfo\n",
      "    filename = getsourcefile(frame) or getfile(frame)\n",
      "  File \"C:\\Users\\Misha\\anaconda3\\lib\\inspect.py\", line 709, in getsourcefile\n",
      "    if getattr(getmodule(object, filename), '__loader__', None) is not None:\n",
      "  File \"C:\\Users\\Misha\\anaconda3\\lib\\inspect.py\", line 755, in getmodule\n",
      "    os.path.realpath(f)] = module.__name__\n",
      "  File \"C:\\Users\\Misha\\anaconda3\\lib\\ntpath.py\", line 647, in realpath\n",
      "    path = _getfinalpathname(path)\n",
      "KeyboardInterrupt\n"
     ]
    }
   ],
   "source": [
    "fol2 = \"vorobeva3\"\n",
    "\n",
    "for i in range(2, 91):\n",
    "    test_file = tf.io.read_file(fol2 + \"/\" + str(i) + \".mp3\")\n",
    "    test_audio = tfio.audio.decode_mp3(test_file)\n",
    "    rows, columns = test_audio.shape\n",
    "    mas_len = len(test_audio)\n",
    "    true_audio = tf.reshape(test_audio, [rows * columns])\n",
    "    np.save(\"numpy_array/\" + fol2 + \"_np/\" +  str(i) + \".npy\", true_audio)"
   ],
   "metadata": {
    "collapsed": false,
    "pycharm": {
     "name": "#%%\n",
     "is_executing": true
    }
   }
  },
  {
   "cell_type": "code",
   "execution_count": 2,
   "outputs": [
    {
     "name": "stdout",
     "output_type": "stream",
     "text": [
      "ERROR! Session/line number was not unique in database. History logging moved to new session 23\n"
     ]
    },
    {
     "name": "stderr",
     "output_type": "stream",
     "text": [
      "ERROR:root:Internal Python error in the inspect module.\n",
      "Below is the traceback from this internal error.\n",
      "\n",
      "ERROR:root:Internal Python error in the inspect module.\n",
      "Below is the traceback from this internal error.\n",
      "\n"
     ]
    },
    {
     "name": "stdout",
     "output_type": "stream",
     "text": [
      "Traceback (most recent call last):\n",
      "  File \"C:\\Users\\Misha\\anaconda3\\lib\\site-packages\\IPython\\core\\interactiveshell.py\", line 3444, in run_code\n",
      "    exec(code_obj, self.user_global_ns, self.user_ns)\n",
      "  File \"C:\\Users\\Misha\\AppData\\Local\\Temp/ipykernel_10032/1616585568.py\", line 9, in <module>\n",
      "    test_file = tf.io.read_file(fol3 + \"/\" + str(i) + \".mp3\")\n",
      "  File \"C:\\Users\\Misha\\anaconda3\\lib\\site-packages\\tensorflow\\python\\ops\\io_ops.py\", line 133, in read_file\n",
      "    return gen_io_ops.read_file(filename, name)\n",
      "  File \"C:\\Users\\Misha\\anaconda3\\lib\\site-packages\\tensorflow\\python\\ops\\gen_io_ops.py\", line 565, in read_file\n",
      "    return read_file_eager_fallback(\n",
      "  File \"C:\\Users\\Misha\\anaconda3\\lib\\site-packages\\tensorflow\\python\\ops\\gen_io_ops.py\", line 588, in read_file_eager_fallback\n",
      "    _result = _execute.execute(b\"ReadFile\", 1, inputs=_inputs_flat,\n",
      "  File \"C:\\Users\\Misha\\anaconda3\\lib\\site-packages\\tensorflow\\python\\eager\\execute.py\", line 54, in quick_execute\n",
      "    tensors = pywrap_tfe.TFE_Py_Execute(ctx._handle, device_name, op_name,\n",
      "KeyboardInterrupt\n",
      "\n",
      "During handling of the above exception, another exception occurred:\n",
      "\n",
      "Traceback (most recent call last):\n",
      "  File \"C:\\Users\\Misha\\anaconda3\\lib\\site-packages\\IPython\\core\\interactiveshell.py\", line 2064, in showtraceback\n",
      "    stb = value._render_traceback_()\n",
      "AttributeError: 'KeyboardInterrupt' object has no attribute '_render_traceback_'\n",
      "\n",
      "During handling of the above exception, another exception occurred:\n",
      "\n",
      "Traceback (most recent call last):\n",
      "  File \"C:\\Users\\Misha\\anaconda3\\lib\\site-packages\\IPython\\core\\ultratb.py\", line 1101, in get_records\n",
      "    return _fixed_getinnerframes(etb, number_of_lines_of_context, tb_offset)\n",
      "  File \"C:\\Users\\Misha\\anaconda3\\lib\\site-packages\\IPython\\core\\ultratb.py\", line 248, in wrapped\n",
      "    return f(*args, **kwargs)\n",
      "  File \"C:\\Users\\Misha\\anaconda3\\lib\\site-packages\\IPython\\core\\ultratb.py\", line 281, in _fixed_getinnerframes\n",
      "    records = fix_frame_records_filenames(inspect.getinnerframes(etb, context))\n",
      "  File \"C:\\Users\\Misha\\anaconda3\\lib\\inspect.py\", line 1541, in getinnerframes\n",
      "    frameinfo = (tb.tb_frame,) + getframeinfo(tb, context)\n",
      "  File \"C:\\Users\\Misha\\anaconda3\\lib\\inspect.py\", line 1499, in getframeinfo\n",
      "    filename = getsourcefile(frame) or getfile(frame)\n",
      "  File \"C:\\Users\\Misha\\anaconda3\\lib\\inspect.py\", line 709, in getsourcefile\n",
      "    if getattr(getmodule(object, filename), '__loader__', None) is not None:\n",
      "  File \"C:\\Users\\Misha\\anaconda3\\lib\\inspect.py\", line 755, in getmodule\n",
      "    os.path.realpath(f)] = module.__name__\n",
      "  File \"C:\\Users\\Misha\\anaconda3\\lib\\ntpath.py\", line 664, in realpath\n",
      "    if _getfinalpathname(spath) == path:\n",
      "KeyboardInterrupt\n",
      "Traceback (most recent call last):\n",
      "  File \"C:\\Users\\Misha\\anaconda3\\lib\\site-packages\\IPython\\core\\interactiveshell.py\", line 3444, in run_code\n",
      "    exec(code_obj, self.user_global_ns, self.user_ns)\n",
      "  File \"C:\\Users\\Misha\\AppData\\Local\\Temp/ipykernel_10032/1616585568.py\", line 9, in <module>\n",
      "    test_file = tf.io.read_file(fol3 + \"/\" + str(i) + \".mp3\")\n",
      "  File \"C:\\Users\\Misha\\anaconda3\\lib\\site-packages\\tensorflow\\python\\ops\\io_ops.py\", line 133, in read_file\n",
      "    return gen_io_ops.read_file(filename, name)\n",
      "  File \"C:\\Users\\Misha\\anaconda3\\lib\\site-packages\\tensorflow\\python\\ops\\gen_io_ops.py\", line 565, in read_file\n",
      "    return read_file_eager_fallback(\n",
      "  File \"C:\\Users\\Misha\\anaconda3\\lib\\site-packages\\tensorflow\\python\\ops\\gen_io_ops.py\", line 588, in read_file_eager_fallback\n",
      "    _result = _execute.execute(b\"ReadFile\", 1, inputs=_inputs_flat,\n",
      "  File \"C:\\Users\\Misha\\anaconda3\\lib\\site-packages\\tensorflow\\python\\eager\\execute.py\", line 54, in quick_execute\n",
      "    tensors = pywrap_tfe.TFE_Py_Execute(ctx._handle, device_name, op_name,\n",
      "KeyboardInterrupt\n",
      "\n",
      "During handling of the above exception, another exception occurred:\n",
      "\n",
      "Traceback (most recent call last):\n",
      "  File \"C:\\Users\\Misha\\anaconda3\\lib\\site-packages\\IPython\\core\\interactiveshell.py\", line 2064, in showtraceback\n",
      "    stb = value._render_traceback_()\n",
      "AttributeError: 'KeyboardInterrupt' object has no attribute '_render_traceback_'\n",
      "\n",
      "During handling of the above exception, another exception occurred:\n",
      "\n",
      "Traceback (most recent call last):\n",
      "  File \"C:\\Users\\Misha\\anaconda3\\lib\\site-packages\\IPython\\core\\interactiveshell.py\", line 3364, in run_ast_nodes\n",
      "    if (await self.run_code(code, result,  async_=asy)):\n",
      "  File \"C:\\Users\\Misha\\anaconda3\\lib\\site-packages\\IPython\\core\\interactiveshell.py\", line 3461, in run_code\n",
      "    self.showtraceback(running_compiled_code=True)\n",
      "  File \"C:\\Users\\Misha\\anaconda3\\lib\\site-packages\\IPython\\core\\interactiveshell.py\", line 2066, in showtraceback\n",
      "    stb = self.InteractiveTB.structured_traceback(etype,\n",
      "  File \"C:\\Users\\Misha\\anaconda3\\lib\\site-packages\\IPython\\core\\ultratb.py\", line 1367, in structured_traceback\n",
      "    return FormattedTB.structured_traceback(\n",
      "  File \"C:\\Users\\Misha\\anaconda3\\lib\\site-packages\\IPython\\core\\ultratb.py\", line 1267, in structured_traceback\n",
      "    return VerboseTB.structured_traceback(\n",
      "  File \"C:\\Users\\Misha\\anaconda3\\lib\\site-packages\\IPython\\core\\ultratb.py\", line 1124, in structured_traceback\n",
      "    formatted_exception = self.format_exception_as_a_whole(etype, evalue, etb, number_of_lines_of_context,\n",
      "  File \"C:\\Users\\Misha\\anaconda3\\lib\\site-packages\\IPython\\core\\ultratb.py\", line 1082, in format_exception_as_a_whole\n",
      "    last_unique, recursion_repeat = find_recursion(orig_etype, evalue, records)\n",
      "  File \"C:\\Users\\Misha\\anaconda3\\lib\\site-packages\\IPython\\core\\ultratb.py\", line 382, in find_recursion\n",
      "    return len(records), 0\n",
      "TypeError: object of type 'NoneType' has no len()\n",
      "\n",
      "During handling of the above exception, another exception occurred:\n",
      "\n",
      "Traceback (most recent call last):\n",
      "  File \"C:\\Users\\Misha\\anaconda3\\lib\\site-packages\\IPython\\core\\interactiveshell.py\", line 2064, in showtraceback\n",
      "    stb = value._render_traceback_()\n",
      "AttributeError: 'TypeError' object has no attribute '_render_traceback_'\n",
      "\n",
      "During handling of the above exception, another exception occurred:\n",
      "\n",
      "Traceback (most recent call last):\n",
      "  File \"C:\\Users\\Misha\\anaconda3\\lib\\site-packages\\IPython\\core\\ultratb.py\", line 1101, in get_records\n",
      "    return _fixed_getinnerframes(etb, number_of_lines_of_context, tb_offset)\n",
      "  File \"C:\\Users\\Misha\\anaconda3\\lib\\site-packages\\IPython\\core\\ultratb.py\", line 248, in wrapped\n",
      "    return f(*args, **kwargs)\n",
      "  File \"C:\\Users\\Misha\\anaconda3\\lib\\site-packages\\IPython\\core\\ultratb.py\", line 281, in _fixed_getinnerframes\n",
      "    records = fix_frame_records_filenames(inspect.getinnerframes(etb, context))\n",
      "  File \"C:\\Users\\Misha\\anaconda3\\lib\\inspect.py\", line 1541, in getinnerframes\n",
      "    frameinfo = (tb.tb_frame,) + getframeinfo(tb, context)\n",
      "  File \"C:\\Users\\Misha\\anaconda3\\lib\\inspect.py\", line 1499, in getframeinfo\n",
      "    filename = getsourcefile(frame) or getfile(frame)\n",
      "  File \"C:\\Users\\Misha\\anaconda3\\lib\\inspect.py\", line 709, in getsourcefile\n",
      "    if getattr(getmodule(object, filename), '__loader__', None) is not None:\n",
      "  File \"C:\\Users\\Misha\\anaconda3\\lib\\inspect.py\", line 755, in getmodule\n",
      "    os.path.realpath(f)] = module.__name__\n",
      "  File \"C:\\Users\\Misha\\anaconda3\\lib\\ntpath.py\", line 664, in realpath\n",
      "    if _getfinalpathname(spath) == path:\n",
      "KeyboardInterrupt\n"
     ]
    },
    {
     "ename": "TypeError",
     "evalue": "object of type 'NoneType' has no len()",
     "output_type": "error",
     "traceback": [
      "\u001B[1;31m---------------------------------------------------------------------------\u001B[0m",
      "\u001B[1;31mKeyboardInterrupt\u001B[0m                         Traceback (most recent call last)",
      "    \u001B[1;31m[... skipping hidden 1 frame]\u001B[0m\n",
      "\u001B[1;32m~\\AppData\\Local\\Temp/ipykernel_10032/1616585568.py\u001B[0m in \u001B[0;36m<module>\u001B[1;34m\u001B[0m\n\u001B[0;32m      8\u001B[0m     \u001B[1;31m# test_file = tf.io.read_file(fol3 + \"/\" + str(i) + \".mp3\")\u001B[0m\u001B[1;33m\u001B[0m\u001B[1;33m\u001B[0m\u001B[0m\n\u001B[1;32m----> 9\u001B[1;33m     \u001B[0mtest_file\u001B[0m \u001B[1;33m=\u001B[0m \u001B[0mtf\u001B[0m\u001B[1;33m.\u001B[0m\u001B[0mio\u001B[0m\u001B[1;33m.\u001B[0m\u001B[0mread_file\u001B[0m\u001B[1;33m(\u001B[0m\u001B[0mfol3\u001B[0m \u001B[1;33m+\u001B[0m \u001B[1;34m\"/\"\u001B[0m \u001B[1;33m+\u001B[0m \u001B[0mstr\u001B[0m\u001B[1;33m(\u001B[0m\u001B[0mi\u001B[0m\u001B[1;33m)\u001B[0m \u001B[1;33m+\u001B[0m \u001B[1;34m\".mp3\"\u001B[0m\u001B[1;33m)\u001B[0m\u001B[1;33m\u001B[0m\u001B[1;33m\u001B[0m\u001B[0m\n\u001B[0m\u001B[0;32m     10\u001B[0m     \u001B[0mtest_audio\u001B[0m \u001B[1;33m=\u001B[0m \u001B[0mtfio\u001B[0m\u001B[1;33m.\u001B[0m\u001B[0maudio\u001B[0m\u001B[1;33m.\u001B[0m\u001B[0mdecode_mp3\u001B[0m\u001B[1;33m(\u001B[0m\u001B[0mtest_file\u001B[0m\u001B[1;33m)\u001B[0m\u001B[1;33m\u001B[0m\u001B[1;33m\u001B[0m\u001B[0m\n",
      "\u001B[1;32m~\\anaconda3\\lib\\site-packages\\tensorflow\\python\\ops\\io_ops.py\u001B[0m in \u001B[0;36mread_file\u001B[1;34m(filename, name)\u001B[0m\n\u001B[0;32m    132\u001B[0m   \"\"\"\n\u001B[1;32m--> 133\u001B[1;33m   \u001B[1;32mreturn\u001B[0m \u001B[0mgen_io_ops\u001B[0m\u001B[1;33m.\u001B[0m\u001B[0mread_file\u001B[0m\u001B[1;33m(\u001B[0m\u001B[0mfilename\u001B[0m\u001B[1;33m,\u001B[0m \u001B[0mname\u001B[0m\u001B[1;33m)\u001B[0m\u001B[1;33m\u001B[0m\u001B[1;33m\u001B[0m\u001B[0m\n\u001B[0m\u001B[0;32m    134\u001B[0m \u001B[1;33m\u001B[0m\u001B[0m\n",
      "\u001B[1;32m~\\anaconda3\\lib\\site-packages\\tensorflow\\python\\ops\\gen_io_ops.py\u001B[0m in \u001B[0;36mread_file\u001B[1;34m(filename, name)\u001B[0m\n\u001B[0;32m    564\u001B[0m     \u001B[1;32mtry\u001B[0m\u001B[1;33m:\u001B[0m\u001B[1;33m\u001B[0m\u001B[1;33m\u001B[0m\u001B[0m\n\u001B[1;32m--> 565\u001B[1;33m       return read_file_eager_fallback(\n\u001B[0m\u001B[0;32m    566\u001B[0m           filename, name=name, ctx=_ctx)\n",
      "\u001B[1;32m~\\anaconda3\\lib\\site-packages\\tensorflow\\python\\ops\\gen_io_ops.py\u001B[0m in \u001B[0;36mread_file_eager_fallback\u001B[1;34m(filename, name, ctx)\u001B[0m\n\u001B[0;32m    587\u001B[0m   \u001B[0m_attrs\u001B[0m \u001B[1;33m=\u001B[0m \u001B[1;32mNone\u001B[0m\u001B[1;33m\u001B[0m\u001B[1;33m\u001B[0m\u001B[0m\n\u001B[1;32m--> 588\u001B[1;33m   _result = _execute.execute(b\"ReadFile\", 1, inputs=_inputs_flat,\n\u001B[0m\u001B[0;32m    589\u001B[0m                              attrs=_attrs, ctx=ctx, name=name)\n",
      "\u001B[1;32m~\\anaconda3\\lib\\site-packages\\tensorflow\\python\\eager\\execute.py\u001B[0m in \u001B[0;36mquick_execute\u001B[1;34m(op_name, num_outputs, inputs, attrs, ctx, name)\u001B[0m\n\u001B[0;32m     53\u001B[0m     \u001B[0mctx\u001B[0m\u001B[1;33m.\u001B[0m\u001B[0mensure_initialized\u001B[0m\u001B[1;33m(\u001B[0m\u001B[1;33m)\u001B[0m\u001B[1;33m\u001B[0m\u001B[1;33m\u001B[0m\u001B[0m\n\u001B[1;32m---> 54\u001B[1;33m     tensors = pywrap_tfe.TFE_Py_Execute(ctx._handle, device_name, op_name,\n\u001B[0m\u001B[0;32m     55\u001B[0m                                         inputs, attrs, num_outputs)\n",
      "\u001B[1;31mKeyboardInterrupt\u001B[0m: ",
      "\nDuring handling of the above exception, another exception occurred:\n",
      "\u001B[1;31mAttributeError\u001B[0m                            Traceback (most recent call last)",
      "\u001B[1;32m~\\anaconda3\\lib\\site-packages\\IPython\\core\\interactiveshell.py\u001B[0m in \u001B[0;36mshowtraceback\u001B[1;34m(self, exc_tuple, filename, tb_offset, exception_only, running_compiled_code)\u001B[0m\n\u001B[0;32m   2063\u001B[0m                         \u001B[1;31m# in the engines. This should return a list of strings.\u001B[0m\u001B[1;33m\u001B[0m\u001B[1;33m\u001B[0m\u001B[0m\n\u001B[1;32m-> 2064\u001B[1;33m                         \u001B[0mstb\u001B[0m \u001B[1;33m=\u001B[0m \u001B[0mvalue\u001B[0m\u001B[1;33m.\u001B[0m\u001B[0m_render_traceback_\u001B[0m\u001B[1;33m(\u001B[0m\u001B[1;33m)\u001B[0m\u001B[1;33m\u001B[0m\u001B[1;33m\u001B[0m\u001B[0m\n\u001B[0m\u001B[0;32m   2065\u001B[0m                     \u001B[1;32mexcept\u001B[0m \u001B[0mException\u001B[0m\u001B[1;33m:\u001B[0m\u001B[1;33m\u001B[0m\u001B[1;33m\u001B[0m\u001B[0m\n",
      "\u001B[1;31mAttributeError\u001B[0m: 'KeyboardInterrupt' object has no attribute '_render_traceback_'",
      "\nDuring handling of the above exception, another exception occurred:\n",
      "\u001B[1;31mTypeError\u001B[0m                                 Traceback (most recent call last)",
      "\u001B[1;32m~\\anaconda3\\lib\\site-packages\\IPython\\core\\interactiveshell.py\u001B[0m in \u001B[0;36mrun_ast_nodes\u001B[1;34m(self, nodelist, cell_name, interactivity, compiler, result)\u001B[0m\n\u001B[0;32m   3363\u001B[0m                         \u001B[0masy\u001B[0m \u001B[1;33m=\u001B[0m \u001B[0mcompare\u001B[0m\u001B[1;33m(\u001B[0m\u001B[0mcode\u001B[0m\u001B[1;33m)\u001B[0m\u001B[1;33m\u001B[0m\u001B[1;33m\u001B[0m\u001B[0m\n\u001B[1;32m-> 3364\u001B[1;33m                     \u001B[1;32mif\u001B[0m \u001B[1;33m(\u001B[0m\u001B[1;32mawait\u001B[0m \u001B[0mself\u001B[0m\u001B[1;33m.\u001B[0m\u001B[0mrun_code\u001B[0m\u001B[1;33m(\u001B[0m\u001B[0mcode\u001B[0m\u001B[1;33m,\u001B[0m \u001B[0mresult\u001B[0m\u001B[1;33m,\u001B[0m  \u001B[0masync_\u001B[0m\u001B[1;33m=\u001B[0m\u001B[0masy\u001B[0m\u001B[1;33m)\u001B[0m\u001B[1;33m)\u001B[0m\u001B[1;33m:\u001B[0m\u001B[1;33m\u001B[0m\u001B[1;33m\u001B[0m\u001B[0m\n\u001B[0m\u001B[0;32m   3365\u001B[0m                         \u001B[1;32mreturn\u001B[0m \u001B[1;32mTrue\u001B[0m\u001B[1;33m\u001B[0m\u001B[1;33m\u001B[0m\u001B[0m\n",
      "    \u001B[1;31m[... skipping hidden 1 frame]\u001B[0m\n",
      "\u001B[1;32m~\\anaconda3\\lib\\site-packages\\IPython\\core\\interactiveshell.py\u001B[0m in \u001B[0;36mshowtraceback\u001B[1;34m(self, exc_tuple, filename, tb_offset, exception_only, running_compiled_code)\u001B[0m\n\u001B[0;32m   2065\u001B[0m                     \u001B[1;32mexcept\u001B[0m \u001B[0mException\u001B[0m\u001B[1;33m:\u001B[0m\u001B[1;33m\u001B[0m\u001B[1;33m\u001B[0m\u001B[0m\n\u001B[1;32m-> 2066\u001B[1;33m                         stb = self.InteractiveTB.structured_traceback(etype,\n\u001B[0m\u001B[0;32m   2067\u001B[0m                                             value, tb, tb_offset=tb_offset)\n",
      "\u001B[1;32m~\\anaconda3\\lib\\site-packages\\IPython\\core\\ultratb.py\u001B[0m in \u001B[0;36mstructured_traceback\u001B[1;34m(self, etype, value, tb, tb_offset, number_of_lines_of_context)\u001B[0m\n\u001B[0;32m   1366\u001B[0m             \u001B[0mself\u001B[0m\u001B[1;33m.\u001B[0m\u001B[0mtb\u001B[0m \u001B[1;33m=\u001B[0m \u001B[0mtb\u001B[0m\u001B[1;33m\u001B[0m\u001B[1;33m\u001B[0m\u001B[0m\n\u001B[1;32m-> 1367\u001B[1;33m         return FormattedTB.structured_traceback(\n\u001B[0m\u001B[0;32m   1368\u001B[0m             self, etype, value, tb, tb_offset, number_of_lines_of_context)\n",
      "\u001B[1;32m~\\anaconda3\\lib\\site-packages\\IPython\\core\\ultratb.py\u001B[0m in \u001B[0;36mstructured_traceback\u001B[1;34m(self, etype, value, tb, tb_offset, number_of_lines_of_context)\u001B[0m\n\u001B[0;32m   1266\u001B[0m             \u001B[1;31m# Verbose modes need a full traceback\u001B[0m\u001B[1;33m\u001B[0m\u001B[1;33m\u001B[0m\u001B[0m\n\u001B[1;32m-> 1267\u001B[1;33m             return VerboseTB.structured_traceback(\n\u001B[0m\u001B[0;32m   1268\u001B[0m                 \u001B[0mself\u001B[0m\u001B[1;33m,\u001B[0m \u001B[0metype\u001B[0m\u001B[1;33m,\u001B[0m \u001B[0mvalue\u001B[0m\u001B[1;33m,\u001B[0m \u001B[0mtb\u001B[0m\u001B[1;33m,\u001B[0m \u001B[0mtb_offset\u001B[0m\u001B[1;33m,\u001B[0m \u001B[0mnumber_of_lines_of_context\u001B[0m\u001B[1;33m\u001B[0m\u001B[1;33m\u001B[0m\u001B[0m\n",
      "\u001B[1;32m~\\anaconda3\\lib\\site-packages\\IPython\\core\\ultratb.py\u001B[0m in \u001B[0;36mstructured_traceback\u001B[1;34m(self, etype, evalue, etb, tb_offset, number_of_lines_of_context)\u001B[0m\n\u001B[0;32m   1123\u001B[0m \u001B[1;33m\u001B[0m\u001B[0m\n\u001B[1;32m-> 1124\u001B[1;33m         formatted_exception = self.format_exception_as_a_whole(etype, evalue, etb, number_of_lines_of_context,\n\u001B[0m\u001B[0;32m   1125\u001B[0m                                                                tb_offset)\n",
      "\u001B[1;32m~\\anaconda3\\lib\\site-packages\\IPython\\core\\ultratb.py\u001B[0m in \u001B[0;36mformat_exception_as_a_whole\u001B[1;34m(self, etype, evalue, etb, number_of_lines_of_context, tb_offset)\u001B[0m\n\u001B[0;32m   1081\u001B[0m \u001B[1;33m\u001B[0m\u001B[0m\n\u001B[1;32m-> 1082\u001B[1;33m         \u001B[0mlast_unique\u001B[0m\u001B[1;33m,\u001B[0m \u001B[0mrecursion_repeat\u001B[0m \u001B[1;33m=\u001B[0m \u001B[0mfind_recursion\u001B[0m\u001B[1;33m(\u001B[0m\u001B[0morig_etype\u001B[0m\u001B[1;33m,\u001B[0m \u001B[0mevalue\u001B[0m\u001B[1;33m,\u001B[0m \u001B[0mrecords\u001B[0m\u001B[1;33m)\u001B[0m\u001B[1;33m\u001B[0m\u001B[1;33m\u001B[0m\u001B[0m\n\u001B[0m\u001B[0;32m   1083\u001B[0m \u001B[1;33m\u001B[0m\u001B[0m\n",
      "\u001B[1;32m~\\anaconda3\\lib\\site-packages\\IPython\\core\\ultratb.py\u001B[0m in \u001B[0;36mfind_recursion\u001B[1;34m(etype, value, records)\u001B[0m\n\u001B[0;32m    381\u001B[0m     \u001B[1;32mif\u001B[0m \u001B[1;32mnot\u001B[0m \u001B[0mis_recursion_error\u001B[0m\u001B[1;33m(\u001B[0m\u001B[0metype\u001B[0m\u001B[1;33m,\u001B[0m \u001B[0mvalue\u001B[0m\u001B[1;33m,\u001B[0m \u001B[0mrecords\u001B[0m\u001B[1;33m)\u001B[0m\u001B[1;33m:\u001B[0m\u001B[1;33m\u001B[0m\u001B[1;33m\u001B[0m\u001B[0m\n\u001B[1;32m--> 382\u001B[1;33m         \u001B[1;32mreturn\u001B[0m \u001B[0mlen\u001B[0m\u001B[1;33m(\u001B[0m\u001B[0mrecords\u001B[0m\u001B[1;33m)\u001B[0m\u001B[1;33m,\u001B[0m \u001B[1;36m0\u001B[0m\u001B[1;33m\u001B[0m\u001B[1;33m\u001B[0m\u001B[0m\n\u001B[0m\u001B[0;32m    383\u001B[0m \u001B[1;33m\u001B[0m\u001B[0m\n",
      "\u001B[1;31mTypeError\u001B[0m: object of type 'NoneType' has no len()",
      "\nDuring handling of the above exception, another exception occurred:\n",
      "\u001B[1;31mAttributeError\u001B[0m                            Traceback (most recent call last)",
      "\u001B[1;32m~\\anaconda3\\lib\\site-packages\\IPython\\core\\interactiveshell.py\u001B[0m in \u001B[0;36mshowtraceback\u001B[1;34m(self, exc_tuple, filename, tb_offset, exception_only, running_compiled_code)\u001B[0m\n\u001B[0;32m   2063\u001B[0m                         \u001B[1;31m# in the engines. This should return a list of strings.\u001B[0m\u001B[1;33m\u001B[0m\u001B[1;33m\u001B[0m\u001B[0m\n\u001B[1;32m-> 2064\u001B[1;33m                         \u001B[0mstb\u001B[0m \u001B[1;33m=\u001B[0m \u001B[0mvalue\u001B[0m\u001B[1;33m.\u001B[0m\u001B[0m_render_traceback_\u001B[0m\u001B[1;33m(\u001B[0m\u001B[1;33m)\u001B[0m\u001B[1;33m\u001B[0m\u001B[1;33m\u001B[0m\u001B[0m\n\u001B[0m\u001B[0;32m   2065\u001B[0m                     \u001B[1;32mexcept\u001B[0m \u001B[0mException\u001B[0m\u001B[1;33m:\u001B[0m\u001B[1;33m\u001B[0m\u001B[1;33m\u001B[0m\u001B[0m\n",
      "\u001B[1;31mAttributeError\u001B[0m: 'TypeError' object has no attribute '_render_traceback_'",
      "\nDuring handling of the above exception, another exception occurred:\n",
      "\u001B[1;31mTypeError\u001B[0m                                 Traceback (most recent call last)",
      "\u001B[1;32m~\\anaconda3\\lib\\site-packages\\IPython\\core\\async_helpers.py\u001B[0m in \u001B[0;36m_pseudo_sync_runner\u001B[1;34m(coro)\u001B[0m\n\u001B[0;32m     66\u001B[0m     \"\"\"\n\u001B[0;32m     67\u001B[0m     \u001B[1;32mtry\u001B[0m\u001B[1;33m:\u001B[0m\u001B[1;33m\u001B[0m\u001B[1;33m\u001B[0m\u001B[0m\n\u001B[1;32m---> 68\u001B[1;33m         \u001B[0mcoro\u001B[0m\u001B[1;33m.\u001B[0m\u001B[0msend\u001B[0m\u001B[1;33m(\u001B[0m\u001B[1;32mNone\u001B[0m\u001B[1;33m)\u001B[0m\u001B[1;33m\u001B[0m\u001B[1;33m\u001B[0m\u001B[0m\n\u001B[0m\u001B[0;32m     69\u001B[0m     \u001B[1;32mexcept\u001B[0m \u001B[0mStopIteration\u001B[0m \u001B[1;32mas\u001B[0m \u001B[0mexc\u001B[0m\u001B[1;33m:\u001B[0m\u001B[1;33m\u001B[0m\u001B[1;33m\u001B[0m\u001B[0m\n\u001B[0;32m     70\u001B[0m         \u001B[1;32mreturn\u001B[0m \u001B[0mexc\u001B[0m\u001B[1;33m.\u001B[0m\u001B[0mvalue\u001B[0m\u001B[1;33m\u001B[0m\u001B[1;33m\u001B[0m\u001B[0m\n",
      "\u001B[1;32m~\\anaconda3\\lib\\site-packages\\IPython\\core\\interactiveshell.py\u001B[0m in \u001B[0;36mrun_cell_async\u001B[1;34m(self, raw_cell, store_history, silent, shell_futures, transformed_cell, preprocessing_exc_tuple)\u001B[0m\n\u001B[0;32m   3170\u001B[0m                     \u001B[0minteractivity\u001B[0m \u001B[1;33m=\u001B[0m \u001B[1;34m'async'\u001B[0m\u001B[1;33m\u001B[0m\u001B[1;33m\u001B[0m\u001B[0m\n\u001B[0;32m   3171\u001B[0m \u001B[1;33m\u001B[0m\u001B[0m\n\u001B[1;32m-> 3172\u001B[1;33m                 has_raised = await self.run_ast_nodes(code_ast.body, cell_name,\n\u001B[0m\u001B[0;32m   3173\u001B[0m                        interactivity=interactivity, compiler=compiler, result=result)\n\u001B[0;32m   3174\u001B[0m \u001B[1;33m\u001B[0m\u001B[0m\n",
      "\u001B[1;32m~\\anaconda3\\lib\\site-packages\\IPython\\core\\interactiveshell.py\u001B[0m in \u001B[0;36mrun_ast_nodes\u001B[1;34m(self, nodelist, cell_name, interactivity, compiler, result)\u001B[0m\n\u001B[0;32m   3381\u001B[0m             \u001B[1;32mif\u001B[0m \u001B[0mresult\u001B[0m\u001B[1;33m:\u001B[0m\u001B[1;33m\u001B[0m\u001B[1;33m\u001B[0m\u001B[0m\n\u001B[0;32m   3382\u001B[0m                 \u001B[0mresult\u001B[0m\u001B[1;33m.\u001B[0m\u001B[0merror_before_exec\u001B[0m \u001B[1;33m=\u001B[0m \u001B[0msys\u001B[0m\u001B[1;33m.\u001B[0m\u001B[0mexc_info\u001B[0m\u001B[1;33m(\u001B[0m\u001B[1;33m)\u001B[0m\u001B[1;33m[\u001B[0m\u001B[1;36m1\u001B[0m\u001B[1;33m]\u001B[0m\u001B[1;33m\u001B[0m\u001B[1;33m\u001B[0m\u001B[0m\n\u001B[1;32m-> 3383\u001B[1;33m             \u001B[0mself\u001B[0m\u001B[1;33m.\u001B[0m\u001B[0mshowtraceback\u001B[0m\u001B[1;33m(\u001B[0m\u001B[1;33m)\u001B[0m\u001B[1;33m\u001B[0m\u001B[1;33m\u001B[0m\u001B[0m\n\u001B[0m\u001B[0;32m   3384\u001B[0m             \u001B[1;32mreturn\u001B[0m \u001B[1;32mTrue\u001B[0m\u001B[1;33m\u001B[0m\u001B[1;33m\u001B[0m\u001B[0m\n\u001B[0;32m   3385\u001B[0m \u001B[1;33m\u001B[0m\u001B[0m\n",
      "\u001B[1;32m~\\anaconda3\\lib\\site-packages\\IPython\\core\\interactiveshell.py\u001B[0m in \u001B[0;36mshowtraceback\u001B[1;34m(self, exc_tuple, filename, tb_offset, exception_only, running_compiled_code)\u001B[0m\n\u001B[0;32m   2064\u001B[0m                         \u001B[0mstb\u001B[0m \u001B[1;33m=\u001B[0m \u001B[0mvalue\u001B[0m\u001B[1;33m.\u001B[0m\u001B[0m_render_traceback_\u001B[0m\u001B[1;33m(\u001B[0m\u001B[1;33m)\u001B[0m\u001B[1;33m\u001B[0m\u001B[1;33m\u001B[0m\u001B[0m\n\u001B[0;32m   2065\u001B[0m                     \u001B[1;32mexcept\u001B[0m \u001B[0mException\u001B[0m\u001B[1;33m:\u001B[0m\u001B[1;33m\u001B[0m\u001B[1;33m\u001B[0m\u001B[0m\n\u001B[1;32m-> 2066\u001B[1;33m                         stb = self.InteractiveTB.structured_traceback(etype,\n\u001B[0m\u001B[0;32m   2067\u001B[0m                                             value, tb, tb_offset=tb_offset)\n\u001B[0;32m   2068\u001B[0m \u001B[1;33m\u001B[0m\u001B[0m\n",
      "\u001B[1;32m~\\anaconda3\\lib\\site-packages\\IPython\\core\\ultratb.py\u001B[0m in \u001B[0;36mstructured_traceback\u001B[1;34m(self, etype, value, tb, tb_offset, number_of_lines_of_context)\u001B[0m\n\u001B[0;32m   1365\u001B[0m         \u001B[1;32melse\u001B[0m\u001B[1;33m:\u001B[0m\u001B[1;33m\u001B[0m\u001B[1;33m\u001B[0m\u001B[0m\n\u001B[0;32m   1366\u001B[0m             \u001B[0mself\u001B[0m\u001B[1;33m.\u001B[0m\u001B[0mtb\u001B[0m \u001B[1;33m=\u001B[0m \u001B[0mtb\u001B[0m\u001B[1;33m\u001B[0m\u001B[1;33m\u001B[0m\u001B[0m\n\u001B[1;32m-> 1367\u001B[1;33m         return FormattedTB.structured_traceback(\n\u001B[0m\u001B[0;32m   1368\u001B[0m             self, etype, value, tb, tb_offset, number_of_lines_of_context)\n\u001B[0;32m   1369\u001B[0m \u001B[1;33m\u001B[0m\u001B[0m\n",
      "\u001B[1;32m~\\anaconda3\\lib\\site-packages\\IPython\\core\\ultratb.py\u001B[0m in \u001B[0;36mstructured_traceback\u001B[1;34m(self, etype, value, tb, tb_offset, number_of_lines_of_context)\u001B[0m\n\u001B[0;32m   1265\u001B[0m         \u001B[1;32mif\u001B[0m \u001B[0mmode\u001B[0m \u001B[1;32min\u001B[0m \u001B[0mself\u001B[0m\u001B[1;33m.\u001B[0m\u001B[0mverbose_modes\u001B[0m\u001B[1;33m:\u001B[0m\u001B[1;33m\u001B[0m\u001B[1;33m\u001B[0m\u001B[0m\n\u001B[0;32m   1266\u001B[0m             \u001B[1;31m# Verbose modes need a full traceback\u001B[0m\u001B[1;33m\u001B[0m\u001B[1;33m\u001B[0m\u001B[0m\n\u001B[1;32m-> 1267\u001B[1;33m             return VerboseTB.structured_traceback(\n\u001B[0m\u001B[0;32m   1268\u001B[0m                 \u001B[0mself\u001B[0m\u001B[1;33m,\u001B[0m \u001B[0metype\u001B[0m\u001B[1;33m,\u001B[0m \u001B[0mvalue\u001B[0m\u001B[1;33m,\u001B[0m \u001B[0mtb\u001B[0m\u001B[1;33m,\u001B[0m \u001B[0mtb_offset\u001B[0m\u001B[1;33m,\u001B[0m \u001B[0mnumber_of_lines_of_context\u001B[0m\u001B[1;33m\u001B[0m\u001B[1;33m\u001B[0m\u001B[0m\n\u001B[0;32m   1269\u001B[0m             )\n",
      "\u001B[1;32m~\\anaconda3\\lib\\site-packages\\IPython\\core\\ultratb.py\u001B[0m in \u001B[0;36mstructured_traceback\u001B[1;34m(self, etype, evalue, etb, tb_offset, number_of_lines_of_context)\u001B[0m\n\u001B[0;32m   1140\u001B[0m         \u001B[0mchained_exc_ids\u001B[0m \u001B[1;33m=\u001B[0m \u001B[0mset\u001B[0m\u001B[1;33m(\u001B[0m\u001B[1;33m)\u001B[0m\u001B[1;33m\u001B[0m\u001B[1;33m\u001B[0m\u001B[0m\n\u001B[0;32m   1141\u001B[0m         \u001B[1;32mwhile\u001B[0m \u001B[0mevalue\u001B[0m\u001B[1;33m:\u001B[0m\u001B[1;33m\u001B[0m\u001B[1;33m\u001B[0m\u001B[0m\n\u001B[1;32m-> 1142\u001B[1;33m             formatted_exceptions += self.format_exception_as_a_whole(etype, evalue, etb, lines_of_context,\n\u001B[0m\u001B[0;32m   1143\u001B[0m                                                                      chained_exceptions_tb_offset)\n\u001B[0;32m   1144\u001B[0m             \u001B[0mexception\u001B[0m \u001B[1;33m=\u001B[0m \u001B[0mself\u001B[0m\u001B[1;33m.\u001B[0m\u001B[0mget_parts_of_chained_exception\u001B[0m\u001B[1;33m(\u001B[0m\u001B[0mevalue\u001B[0m\u001B[1;33m)\u001B[0m\u001B[1;33m\u001B[0m\u001B[1;33m\u001B[0m\u001B[0m\n",
      "\u001B[1;32m~\\anaconda3\\lib\\site-packages\\IPython\\core\\ultratb.py\u001B[0m in \u001B[0;36mformat_exception_as_a_whole\u001B[1;34m(self, etype, evalue, etb, number_of_lines_of_context, tb_offset)\u001B[0m\n\u001B[0;32m   1080\u001B[0m \u001B[1;33m\u001B[0m\u001B[0m\n\u001B[0;32m   1081\u001B[0m \u001B[1;33m\u001B[0m\u001B[0m\n\u001B[1;32m-> 1082\u001B[1;33m         \u001B[0mlast_unique\u001B[0m\u001B[1;33m,\u001B[0m \u001B[0mrecursion_repeat\u001B[0m \u001B[1;33m=\u001B[0m \u001B[0mfind_recursion\u001B[0m\u001B[1;33m(\u001B[0m\u001B[0morig_etype\u001B[0m\u001B[1;33m,\u001B[0m \u001B[0mevalue\u001B[0m\u001B[1;33m,\u001B[0m \u001B[0mrecords\u001B[0m\u001B[1;33m)\u001B[0m\u001B[1;33m\u001B[0m\u001B[1;33m\u001B[0m\u001B[0m\n\u001B[0m\u001B[0;32m   1083\u001B[0m \u001B[1;33m\u001B[0m\u001B[0m\n\u001B[0;32m   1084\u001B[0m         \u001B[0mframes\u001B[0m \u001B[1;33m=\u001B[0m \u001B[0mself\u001B[0m\u001B[1;33m.\u001B[0m\u001B[0mformat_records\u001B[0m\u001B[1;33m(\u001B[0m\u001B[0mrecords\u001B[0m\u001B[1;33m,\u001B[0m \u001B[0mlast_unique\u001B[0m\u001B[1;33m,\u001B[0m \u001B[0mrecursion_repeat\u001B[0m\u001B[1;33m)\u001B[0m\u001B[1;33m\u001B[0m\u001B[1;33m\u001B[0m\u001B[0m\n",
      "\u001B[1;32m~\\anaconda3\\lib\\site-packages\\IPython\\core\\ultratb.py\u001B[0m in \u001B[0;36mfind_recursion\u001B[1;34m(etype, value, records)\u001B[0m\n\u001B[0;32m    380\u001B[0m     \u001B[1;31m# first frame (from in to out) that looks different.\u001B[0m\u001B[1;33m\u001B[0m\u001B[1;33m\u001B[0m\u001B[0m\n\u001B[0;32m    381\u001B[0m     \u001B[1;32mif\u001B[0m \u001B[1;32mnot\u001B[0m \u001B[0mis_recursion_error\u001B[0m\u001B[1;33m(\u001B[0m\u001B[0metype\u001B[0m\u001B[1;33m,\u001B[0m \u001B[0mvalue\u001B[0m\u001B[1;33m,\u001B[0m \u001B[0mrecords\u001B[0m\u001B[1;33m)\u001B[0m\u001B[1;33m:\u001B[0m\u001B[1;33m\u001B[0m\u001B[1;33m\u001B[0m\u001B[0m\n\u001B[1;32m--> 382\u001B[1;33m         \u001B[1;32mreturn\u001B[0m \u001B[0mlen\u001B[0m\u001B[1;33m(\u001B[0m\u001B[0mrecords\u001B[0m\u001B[1;33m)\u001B[0m\u001B[1;33m,\u001B[0m \u001B[1;36m0\u001B[0m\u001B[1;33m\u001B[0m\u001B[1;33m\u001B[0m\u001B[0m\n\u001B[0m\u001B[0;32m    383\u001B[0m \u001B[1;33m\u001B[0m\u001B[0m\n\u001B[0;32m    384\u001B[0m     \u001B[1;31m# Select filename, lineno, func_name to track frames with\u001B[0m\u001B[1;33m\u001B[0m\u001B[1;33m\u001B[0m\u001B[0m\n",
      "\u001B[1;31mTypeError\u001B[0m: object of type 'NoneType' has no len()"
     ]
    }
   ],
   "source": [
    "fol3 = \"borzunov2\"\n",
    "\n",
    "for i in range (1, 216):\n",
    "    if (i == 8):\n",
    "        continue\n",
    "    if (i > 70 and i < 80):\n",
    "        continue\n",
    "    # test_file = tf.io.read_file(fol3 + \"/\" + str(i) + \".mp3\")\n",
    "    test_file = tf.io.read_file(fol3 + \"/\" + str(i) + \".mp3\")\n",
    "    test_audio = tfio.audio.decode_mp3(test_file)\n",
    "\n",
    "    rows, columns = test_audio.shape\n",
    "    mas_len = len(test_audio)\n",
    "    true_audio = tf.reshape(test_audio, [rows * columns])\n",
    "    np.save(\"numpy_array/\" + fol3 + \"_np/\" +  str(i) + \".npy\", true_audio)"
   ],
   "metadata": {
    "collapsed": false,
    "pycharm": {
     "name": "#%%\n"
    }
   }
  },
  {
   "cell_type": "code",
   "execution_count": 6,
   "outputs": [
    {
     "ename": "InvalidArgumentError",
     "evalue": "read 27889920 from 0 failed: -5 [Op:IO>AudioDecodeMP3]",
     "output_type": "error",
     "traceback": [
      "\u001B[1;31m---------------------------------------------------------------------------\u001B[0m",
      "\u001B[1;31mInvalidArgumentError\u001B[0m                      Traceback (most recent call last)",
      "Input \u001B[1;32mIn [6]\u001B[0m, in \u001B[0;36m<cell line: 3>\u001B[1;34m()\u001B[0m\n\u001B[0;32m      5\u001B[0m     \u001B[38;5;28;01mcontinue\u001B[39;00m\n\u001B[0;32m      6\u001B[0m test_file \u001B[38;5;241m=\u001B[39m tf\u001B[38;5;241m.\u001B[39mio\u001B[38;5;241m.\u001B[39mread_file(fol4 \u001B[38;5;241m+\u001B[39m \u001B[38;5;124m\"\u001B[39m\u001B[38;5;124m/\u001B[39m\u001B[38;5;124m\"\u001B[39m \u001B[38;5;241m+\u001B[39m \u001B[38;5;28mstr\u001B[39m(i) \u001B[38;5;241m+\u001B[39m \u001B[38;5;124m\"\u001B[39m\u001B[38;5;124m.mp3\u001B[39m\u001B[38;5;124m\"\u001B[39m)\n\u001B[1;32m----> 7\u001B[0m test_audio \u001B[38;5;241m=\u001B[39m \u001B[43mtfio\u001B[49m\u001B[38;5;241;43m.\u001B[39;49m\u001B[43maudio\u001B[49m\u001B[38;5;241;43m.\u001B[39;49m\u001B[43mdecode_mp3\u001B[49m\u001B[43m(\u001B[49m\u001B[43mtest_file\u001B[49m\u001B[43m)\u001B[49m\n\u001B[0;32m      8\u001B[0m rows, columns \u001B[38;5;241m=\u001B[39m test_audio\u001B[38;5;241m.\u001B[39mshape\n\u001B[0;32m      9\u001B[0m mas_len \u001B[38;5;241m=\u001B[39m \u001B[38;5;28mlen\u001B[39m(test_audio)\n",
      "File \u001B[1;32m~\\anaconda3\\envs\\testing1\\lib\\site-packages\\tensorflow_io\\python\\ops\\audio_ops.py:593\u001B[0m, in \u001B[0;36mdecode_mp3\u001B[1;34m(input, shape, name)\u001B[0m\n\u001B[0;32m    591\u001B[0m \u001B[38;5;28;01mif\u001B[39;00m shape \u001B[38;5;129;01mis\u001B[39;00m \u001B[38;5;28;01mNone\u001B[39;00m:\n\u001B[0;32m    592\u001B[0m     shape \u001B[38;5;241m=\u001B[39m tf\u001B[38;5;241m.\u001B[39mconstant([\u001B[38;5;241m-\u001B[39m\u001B[38;5;241m1\u001B[39m, \u001B[38;5;241m-\u001B[39m\u001B[38;5;241m1\u001B[39m], tf\u001B[38;5;241m.\u001B[39mint64)\n\u001B[1;32m--> 593\u001B[0m \u001B[38;5;28;01mreturn\u001B[39;00m \u001B[43mcore_ops\u001B[49m\u001B[38;5;241;43m.\u001B[39;49m\u001B[43mio_audio_decode_mp3\u001B[49m\u001B[43m(\u001B[49m\u001B[38;5;28;43minput\u001B[39;49m\u001B[43m,\u001B[49m\u001B[43m \u001B[49m\u001B[43mshape\u001B[49m\u001B[38;5;241;43m=\u001B[39;49m\u001B[43mshape\u001B[49m\u001B[43m,\u001B[49m\u001B[43m \u001B[49m\u001B[43mname\u001B[49m\u001B[38;5;241;43m=\u001B[39;49m\u001B[43mname\u001B[49m\u001B[43m)\u001B[49m\n",
      "File \u001B[1;32m<string>:3477\u001B[0m, in \u001B[0;36mio_audio_decode_mp3\u001B[1;34m(input, shape, name)\u001B[0m\n",
      "File \u001B[1;32m~\\anaconda3\\envs\\testing1\\lib\\site-packages\\tensorflow\\python\\framework\\ops.py:7186\u001B[0m, in \u001B[0;36mraise_from_not_ok_status\u001B[1;34m(e, name)\u001B[0m\n\u001B[0;32m   7184\u001B[0m \u001B[38;5;28;01mdef\u001B[39;00m \u001B[38;5;21mraise_from_not_ok_status\u001B[39m(e, name):\n\u001B[0;32m   7185\u001B[0m   e\u001B[38;5;241m.\u001B[39mmessage \u001B[38;5;241m+\u001B[39m\u001B[38;5;241m=\u001B[39m (\u001B[38;5;124m\"\u001B[39m\u001B[38;5;124m name: \u001B[39m\u001B[38;5;124m\"\u001B[39m \u001B[38;5;241m+\u001B[39m name \u001B[38;5;28;01mif\u001B[39;00m name \u001B[38;5;129;01mis\u001B[39;00m \u001B[38;5;129;01mnot\u001B[39;00m \u001B[38;5;28;01mNone\u001B[39;00m \u001B[38;5;28;01melse\u001B[39;00m \u001B[38;5;124m\"\u001B[39m\u001B[38;5;124m\"\u001B[39m)\n\u001B[1;32m-> 7186\u001B[0m   \u001B[38;5;28;01mraise\u001B[39;00m core\u001B[38;5;241m.\u001B[39m_status_to_exception(e) \u001B[38;5;28;01mfrom\u001B[39;00m \u001B[38;5;28mNone\u001B[39m\n",
      "\u001B[1;31mInvalidArgumentError\u001B[0m: read 27889920 from 0 failed: -5 [Op:IO>AudioDecodeMP3]"
     ]
    }
   ],
   "source": [
    "fol4 = \"erizanova1\"\n",
    "\n",
    "for i in range (1, 271):\n",
    "    if i < 54:\n",
    "        continue\n",
    "    test_file = tf.io.read_file(fol4 + \"/\" + str(i) + \".mp3\")\n",
    "    test_audio = tfio.audio.decode_mp3(test_file)\n",
    "    rows, columns = test_audio.shape\n",
    "    mas_len = len(test_audio)\n",
    "    true_audio = tf.reshape(test_audio, [rows * columns])\n",
    "    np.save(\"numpy_array/\" + fol4 + \"_np/\" +  str(i) + \".npy\", true_audio)"
   ],
   "metadata": {
    "collapsed": false,
    "pycharm": {
     "name": "#%%\n"
    }
   }
  },
  {
   "cell_type": "code",
   "execution_count": null,
   "outputs": [],
   "source": [],
   "metadata": {
    "collapsed": false,
    "pycharm": {
     "name": "#%%\n"
    }
   }
  }
 ],
 "metadata": {
  "kernelspec": {
   "display_name": "Python 3",
   "language": "python",
   "name": "python3"
  },
  "language_info": {
   "codemirror_mode": {
    "name": "ipython",
    "version": 2
   },
   "file_extension": ".py",
   "mimetype": "text/x-python",
   "name": "python",
   "nbconvert_exporter": "python",
   "pygments_lexer": "ipython2",
   "version": "2.7.6"
  }
 },
 "nbformat": 4,
 "nbformat_minor": 0
}